<?xml version="1.0" encoding="utf-8"?>
<!-- This URDF was automatically created by SolidWorks to URDF Exporter! Originally created by Stephen Brawner (brawner@gmail.com) 
     Commit Version: 1.6.0-1-g15f4949  Build Version: 1.6.7594.29634
     For more information, please see http://wiki.ros.org/sw_urdf_exporter -->
<robot
  name="adl050_description">
  <link name="base_footprint"/>
  <link
    name="base_link">
    <inertial>
      <origin
        xyz="-2.81899139791371E-17 3.57300580350263E-06 0.10699282910871"
        rpy="0 0 0" />
      <mass
        value="3.24479756388033" />
      <inertia
        ixx="0.0122797131833936"
        ixy="-3.99585571497737E-07"
        ixz="-4.43175806411999E-18"
        iyy="0.0291489353642304"
        iyz="-7.78479526808356E-19"
        izz="0.0303446241116249" />
    </inertial>
    <visual>
      <origin
        xyz="0 0 0"
        rpy="0 0 0" />
      <geometry>
        <mesh
          filename="package://adl050_description/meshes/base_link.STL" />
      </geometry>
      <material
        name="">
        <color
          rgba="0.792156862745098 0.819607843137255 0.933333333333333 1" />
      </material>
    </visual>
    <collision>
      <origin
        xyz="0 0 0"
        rpy="0 0 0" />
      <geometry>
        <mesh
          filename="package://adl050_description/meshes/base_link.STL" />
      </geometry>
    </collision>
  </link>
  <link
    name="l_c_wheel">
    <inertial>
      <origin
        xyz="-0.00676235223108535 -0.212507002930835 0.012281074390865"
        rpy="0 0 0" />
      <mass
        value="9.12428167503571" />
      <inertia
        ixx="0.159051378394952"
        ixy="0.00964421790759014"
        ixz="0.000364069302619026"
        iyy="0.179999983381471"
        iyz="4.9396755472962E-05"
        izz="0.307584701783873" />
    </inertial>
    <visual>
      <origin
        xyz="0 0 0"
        rpy="0 0 0" />
      <geometry>
        <mesh
          filename="package://adl050_description/meshes/l_c_wheel.STL" />
      </geometry>
      <material
        name="">
        <color
          rgba="1 1 1 1" />
      </material>
    </visual>
    <collision>
      <origin
        xyz="0 0 0"
        rpy="0 0 0" />
      <geometry>
        <mesh
          filename="package://adl050_description/meshes/l_c_wheel.STL" />
      </geometry>
    </collision>
  </link>
  <joint
    name="base_footprint_fixed"
    type="fixed">
    <origin
      xyz="0 0 0.035"
      rpy="0 0 0" />
    <parent
      link="base_footprint" />
    <child
      link="base_link" />
  </joint>
  <joint
  <joint
    name="l_c_wheel"
    type="continuous">
    <origin
      xyz="0 0.2165 0.10066"
      rpy="0 0 0" />
    <parent
      link="base_link" />
    <child
      link="l_c_wheel" />
    <axis
      xyz="0 -1 0" />
  </joint>
  <link
    name="r_c_wheel">
    <inertial>
      <origin
        xyz="-0.00676235223124897 0.220992997069165 0.0122810743908647"
        rpy="0 0 0" />
      <mass
        value="9.12428167503571" />
      <inertia
        ixx="0.159051378394952"
        ixy="0.00964421790759014"
        ixz="0.000364069302619026"
        iyy="0.179999983381471"
        iyz="4.93967554730572E-05"
        izz="0.307584701783874" />
    </inertial>
    <visual>
      <origin
        xyz="0 0 0"
        rpy="0 0 0" />
      <geometry>
        <mesh
          filename="package://adl050_description/meshes/r_c_wheel.STL" />
      </geometry>
      <material
        name="">
        <color
          rgba="1 1 1 1" />
      </material>
    </visual>
    <collision>
      <origin
        xyz="0 0 0"
        rpy="0 0 0" />
      <geometry>
        <mesh
          filename="package://adl050_description/meshes/r_c_wheel.STL" />
      </geometry>
    </collision>
  </link>
  <joint
    name="r_c_wheel"
    type="continuous">
    <origin
      xyz="0 -0.217 0.10066"
      rpy="0 0 0" />
    <parent
      link="base_link" />
    <child
      link="r_c_wheel" />
    <axis
      xyz="0 1 0" />
  </joint>
  <link
    name="front_lidar">
    <inertial>
      <origin
        xyz="-0.00602502773981134 1.94527991993012E-07 0.0034585828647056"
        rpy="0 0 0" />
      <mass
        value="0.0538363408125657" />
      <inertia
        ixx="7.61705398238196E-05"
        ixy="4.38165937723868E-10"
        ixz="-4.31814389804301E-07"
        iyy="5.66762094406086E-05"
        iyz="6.24832719631161E-11"
        izz="3.97052801230909E-05" />
    </inertial>
    <visual>
      <origin
        xyz="0 0 0"
        rpy="0 0 0" />
      <geometry>
        <mesh
          filename="package://adl050_description/meshes/front_lidar.STL" />
      </geometry>
      <material
        name="">
        <color
          rgba="0.823529411764706 0.823529411764706 1 1" />
      </material>
    </visual>
    <collision>
      <origin
        xyz="0 0 0"
        rpy="0 0 0" />
      <geometry>
        <mesh
          filename="package://adl050_description/meshes/front_lidar.STL" />
      </geometry>
    </collision>
  </link>
  <joint
    name="front_lidar"
    type="continuous">
    <origin
      xyz="0.275901362416 0.00059151431260001 0.15706040932129"
      rpy="0 0 0" />
    <parent
      link="base_link" />
    <child
      link="front_lidar" />
    <axis
      xyz="0 0 -1" />
  </joint>
  <link
    name="rear_lidar">
    <inertial>
      <origin
        xyz="-0.00602502789702325 1.94374109560661E-07 0.00345858273494148"
        rpy="0 0 0" />
      <mass
        value="0.0538363404783541" />
      <inertia
        ixx="7.61705386918111E-05"
        ixy="4.38230073576721E-10"
        ixz="-4.31814334222836E-07"
        iyy="5.66762084830353E-05"
        iyz="6.26668442679483E-11"
        izz="3.97052799079321E-05" />
    </inertial>
    <visual>
      <origin
        xyz="0 0 0"
        rpy="0 0 0" />
      <geometry>
        <mesh
          filename="package://adl050_description/meshes/rear_lidar.STL" />
      </geometry>
      <material
        name="">
        <color
          rgba="0.823529411764706 0.823529411764706 1 1" />
      </material>
    </visual>
    <collision>
      <origin
        xyz="0 0 0"
        rpy="0 0 0" />
      <geometry>
        <mesh
          filename="package://adl050_description/meshes/rear_lidar.STL" />
      </geometry>
    </collision>
  </link>
  <joint
    name="rear_lidar"
    type="continuous">
    <origin
      xyz="-0.276558991768 0.000591514312599992 0.15730550171629"
      rpy="0 0 3.14159265358979" />
    <parent
      link="base_link" />
    <child
      link="rear_lidar" />
    <axis
      xyz="0 0 -1" />
  </joint>
</robot>